Workbook

Sheet galactic
A1: ra | B1: dec | D1: ra_deg
A2: =raw!I22 -> 6.8666667 | B2: =raw!N22 -> -0.27406158 | D2: =15*(INT(A2)+MOD(A2,1)) -> 103
A3: =raw!I23 -> 6.9333333 | B3: =raw!N23 -> -2.2245892 | D3: =15*(INT(A3)+MOD(A3,1)) -> 104
A4: =raw!I24 -> 7 | B4: =raw!N24 -> -4.169299 | D4: =15*(INT(A4)+MOD(A4,1)) -> 105
A5: =raw!I25 -> 7.0666667 | B5: =raw!N25 -> -6.1031788 | D5: =15*(INT(A5)+MOD(A5,1)) -> 106
A6: =raw!I26 -> 7.1333333 | B6: =raw!N26 -> -8.0213751 | D6: =15*(INT(A6)+MOD(A6,1)) -> 107
A7: =raw!I27 -> 7.2 | B7: =raw!N27 -> -9.9192612 | D7: =15*(INT(A7)+MOD(A7,1)) -> 108
A8: =raw!I28 -> 7.2666667 | B8: =raw!N28 -> -11.792495 | D8: =15*(INT(A8)+MOD(A8,1)) -> 109
A9: =raw!I29 -> 7.3333333 | B9: =raw!N29 -> -13.637068 | D9: =15*(INT(A9)+MOD(A9,1)) -> 110
A10: =raw!I30 -> 7.4 | B10: =raw!N30 -> -15.449346 | D10: =15*(INT(A10)+MOD(A10,1)) -> 111
A11: =raw!I31 -> 7.4666667 | B11: =raw!N31 -> -17.226094 | D11: =15*(INT(A11)+MOD(A11,1)) -> 112
A12: =raw!I32 -> 7.5333333 | B12: =raw!N32 -> -18.964491 | D12: =15*(INT(A12)+MOD(A12,1)) -> 113
A13: =raw!I33 -> 7.6 | B13: =raw!N33 -> -20.662138 | D13: =15*(INT(A13)+MOD(A13,1)) -> 114
... A362: =raw!I382 -> 6.8666667 | B362: =raw!N382 -> -0.27406158 | D362: =15*(INT(A362)+MOD(A362,1)) -> 103

Sheet raw
F5: RA | K5: Dec
D6: Galactic | E6: North | F6: 12 | G6: 51 | H6: 26.3 | I6: =(((H6/60)+G6)/60)+F6 -> 12.857306 | J6: =((((H6/60)+G6)/60)+F6)*15 -> 192.85958 | K6: 27 | L6: 7 | M6: 42 | N6: =(((M6/60)+L6)/60)+K6 -> 27.128333 | R6: delta-p | S6: =N6 -> 27.128333
E7: Center | F7: 17 | G7: 45 | H7: 40 | I7: =(((H7/60)+G7)/60)+F7 -> 17.761111 | J7: =((((H7/60)+G7)/60)+F7)*15 -> 266.41667 | K7: -29 | L7: 0 | M7: 28 | N7: =-((((M7/60)+L7)/60)+ABS(K7)) -> -29.007778 | R7: alpha-p | S7: =J6 -> 192.85958
E8: Center-alt | F8: 17 | G8: 45 | H8: 37 | I8: =(((H8/60)+G8)/60)+F8 -> 17.760278 | J8: =((((H8/60)+G8)/60)+F8)*15 -> 266.40417 | K8: -28 | L8: 56 | M8: 10 | N8: =-((((M8/60)+L8)/60)+ABS(K8)) -> -28.936111
E9: Anticenter | F9: 5 | G9: 45 | H9: 40 | I9: =(((H9/60)+G9)/60)+F9 -> 5.7611111 | J9: =((((H9/60)+G9)/60)+F9)*15 -> 86.416667 | K9: 29 | L9: 0 | M9: 28 | N9: =(((M9/60)+L9)/60)+K9 -> 29.007778
E10: South | F10: 0 | G10: 51 | H10: 26 | I10: =(((H10/60)+G10)/60)+F10 -> 0.85722222 | J10: =((((H10/60)+G10)/60)+F10)*15 -> 12.858333 | K10: -27 | L10: 7 | M10: 42 | N10: =-((((M10/60)+L10)/60)+ABS(K10)) -> -27.128333
I11: =(((H11/60)+G11)/60)+F11 -> 0 | J11: =((((H11/60)+G11)/60)+F11)*15 -> 0 | N11: =(((M11/60)+L11)/60)+K11 -> 0
E12: Eastward | F12: 6 | G12: 51 | H12: 26 | I12: =(((H12/60)+G12)/60)+F12 -> 6.8572222 | J12: =((((H12/60)+G12)/60)+F12)*15 -> 102.85833 | K12: 0 | L12: 0 | M12: 0 | N12: =-((((M12/60)+L12)/60)+ABS(K12)) -> 0
E13: Westward | F13: 18 | G13: 51 | H13: 26 | I13: =(((H13/60)+G13)/60)+F13 -> 18.857222 | J13: =((((H13/60)+G13)/60)+F13)*15 -> 282.85833 | K13: 0 | L13: 0 | M13: 0 | N13: =(((M13/60)+L13)/60)+K13 -> 0
I14: =(((H14/60)+G14)/60)+F14 -> 0 | J14: =((((H14/60)+G14)/60)+F14)*15 -> 0 | N14: =-((((M14/60)+L14)/60)+ABS(K14)) -> 0
I15: =(((H15/60)+G15)/60)+F15 -> 0 | J15: =((((H15/60)+G15)/60)+F15)*15 -> 0 | N15: =(((M15/60)+L15)/60)+K15 -> 0 | V15: =DEGREES(
I16: =(((H16/60)+G16)/60)+F16 -> 0 | J16: =((((H16/60)+G16)/60)+F16)*15 -> 0 | N16: =-((((M16/60)+L16)/60)+ABS(K16)) -> 0 | V16: ATAN(
I17: =(((H17/60)+G17)/60)+F17 -> 0 | J17: =((((H17/60)+G17)/60)+F17)*15 -> 0 | N17: =(((M17/60)+L17)/60)+K17 -> 0 | V17: -(COS(RADIANS(27.12825)) / SIN(RADIANS(27.12825)))
E18: manually | I18: =(((H18/60)+G18)/60)+F18 -> 0 | J18: =((((H18/60)+G18)/60)+F18)*15 -> 0 | K18: -62 | L18: 52 | M18: 19 | N18: =-((((M18/60)+L18)/60)+ABS(K18)) -> -62.871944 | R18: -(cos dp/sin dp) | V18: * COS(RADIANS(A1*15 - 192.85948))
E19: calculated | F19: 12 | G19: 52 | H19: 0 | I19: =(((H19/60)+G19)/60)+F19 -> 12.866667 | J19: =((((H19/60)+G19)/60)+F19)*15 -> 193 | N19: =DEGREES(ATAN(-(COS(RADIANS($S$6))/SIN(RADIANS($S$6)))*COS(RADIANS(J19-$S$7)))) -> -62.871597 | R19: cos(a - ap) | V19: )
F20: 0 | G20: 0 | H20: 0 | I20: =(((H20/60)+G20)/60)+F20 -> 0 | J20: =((((H20/60)+G20)/60)+F20)*15 -> 0 | N20: =DEGREES(ATAN(-(COS(RADIANS($S$6))/SIN(RADIANS($S$6)))*COS(RADIANS(J20-$S$7)))) -> 62.276675 | V20: )
F21: 0 | G21: 0 | H21: 0 | I21: =(((H21/60)+G21)/60)+F21 -> 0 | J21: =((((H21/60)+G21)/60)+F21)*15 -> 0 | N21: =DEGREES(ATAN(-(COS(RADIANS($S$6))/SIN(RADIANS($S$6)))*COS(RADIANS(J21-$S$7)))) -> 62.276675
F22: 6 | G22: 52 | H22: 0 | I22: =(((H22/60)+G22)/60)+F22 -> 6.8666667 | J22: =((((H22/60)+G22)/60)+F22)*15 -> 103 | N22: =DEGREES(ATAN(-(COS(RADIANS($S$6))/SIN(RADIANS($S$6)))*COS(RADIANS(J22-$S$7)))) -> -0.27406158
F23: 6 | G23: 56 | H23: 0 | I23: =(((H23/60)+G23)/60)+F23 -> 6.9333333 | J23: =((((H23/60)+G23)/60)+F23)*15 -> 104 | N23: =DEGREES(ATAN(-(COS(RADIANS($S$6))/SIN(RADIANS($S$6)))*COS(RADIANS(J23-$S$7)))) -> -2.2245892
F24: 7 | G24: 0 | H24: 0 | I24: =(((H24/60)+G24)/60)+F24 -> 7 | J24: =((((H24/60)+G24)/60)+F24)*15 -> 105 | N24: =DEGREES(ATAN(-(COS(RADIANS($S$6))/SIN(RADIANS($S$6)))*COS(RADIANS(J24-$S$7)))) -> -4.169299
F25: 7 | G25: 4 | H25: 0 | I25: =(((H25/60)+G25)/60)+F25 -> 7.0666667 | J25: =((((H25/60)+G25)/60)+F25)*15 -> 106 | N25: =DEGREES(ATAN(-(COS(RADIANS($S$6))/SIN(RADIANS($S$6)))*COS(RADIANS(J25-$S$7)))) -> -6.1031788
F26: 7 | G26: 8 | H26: 0 | I26: =(((H26/60)+G26)/60)+F26 -> 7.1333333 | J26: =((((H26/60)+G26)/60)+F26)*15 -> 107 | N26: =DEGREES(ATAN(-(COS(RADIANS($S$6))/SIN(RADIANS($S$6)))*COS(RADIANS(J26-$S$7)))) -> -8.0213751
F27: 7 | G27: 12 | H27: 0 | I27: =(((H27/60)+G27)/60)+F27 -> 7.2 | J27: =((((H27/60)+G27)/60)+F27)*15 -> 108 | N27: =DEGREES(ATAN(-(COS(RADIANS($S$6))/SIN(RADIANS($S$6)))*COS(RADIANS(J27-$S$7)))) -> -9.9192612
F28: 7 | G28: 16 | H28: 0 | I28: =(((H28/60)+G28)/60)+F28 -> 7.2666667 | J28: =((((H28/60)+G28)/60)+F28)*15 -> 109 | N28: =DEGREES(ATAN(-(COS(RADIANS($S$6))/SIN(RADIANS($S$6)))*COS(RADIANS(J28-$S$7)))) -> -11.792495
F29: 7 | G29: 20 | H29: 0 | I29: =(((H29/60)+G29)/60)+F29 -> 7.3333333 | J29: =((((H29/60)+G29)/60)+F29)*15 -> 110 | N29: =DEGREES(ATAN(-(COS(RADIANS($S$6))/SIN(RADIANS($S$6)))*COS(RADIANS(J29-$S$7)))) -> -13.637068
F30: 7 | G30: 24 | H30: 0 | I30: =(((H30/60)+G30)/60)+F30 -> 7.4 | J30: =((((H30/60)+G30)/60)+F30)*15 -> 111 | N30: =DEGREES(ATAN(-(COS(RADIANS($S$6))/SIN(RADIANS($S$6)))*COS(RADIANS(J30-$S$7)))) -> -15.449346
F31: 7 | G31: 28 | H31: 0 | I31: =(((H31/60)+G31)/60)+F31 -> 7.4666667 | J31: =((((H31/60)+G31)/60)+F31)*15 -> 112 | N31: =DEGREES(ATAN(-(COS(RADIANS($S$6))/SIN(RADIANS($S$6)))*COS(RADIANS(J31-$S$7)))) -> -17.226094
F32: 7 | G32: 32 | H32: 0 | I32: =(((H32/60)+G32)/60)+F32 -> 7.5333333 | J32: =((((H32/60)+G32)/60)+F32)*15 -> 113 | N32: =DEGREES(ATAN(-(COS(RADIANS($S$6))/SIN(RADIANS($S$6)))*COS(RADIANS(J32-$S$7)))) -> -18.964491
... F52: 8 | G52: 52 | H52: 0 | I52: =(((H52/60)+G52)/60)+F52 -> 8.8666667 | J52: =((((H52/60)+G52)/60)+F52)*15 -> 133 | N52: =DEGREES(ATAN(-(COS(RADIANS($S$6))/SIN(RADIANS($S$6)))*COS(RADIANS(J52-$S$7)))) -> -44.422294
F53: 8 | G53: 56 | H53: 0 | I53: =(((H53/60)+G53)/60)+F53 -> 8.9333333 | J53: =((((H53/60)+G53)/60)+F53)*15 -> 134 | N53: =DEGREES(ATAN(-(COS(RADIANS($S$6))/SIN(RADIANS($S$6)))*COS(RADIANS(J53-$S$7)))) -> -45.266428 | U53: ℓ (deg) | V53: RA (J2000) | W53: Dec (J2000) | X53: Notes
F54: 9 | G54: 0 | H54: 0 | I54: =(((H54/60)+G54)/60)+F54 -> 9 | J54: =((((H54/60)+G54)/60)+F54)*15 -> 135 | N54: =DEGREES(ATAN(-(COS(RADIANS($S$6))/SIN(RADIANS($S$6)))*COS(RADIANS(J54-$S$7)))) -> -46.077708 | U54: 0 | V54: 17ᶜ 45ᵐ (266.4°) | W54: −28.9° | X54: Galactic center (HandWiki)
F55: 9 | G55: 4 | H55: 0 | I55: =(((H55/60)+G55)/60)+F55 -> 9.0666667 | J55: =((((H55/60)+G55)/60)+F55)*15 -> 136 | N55: =DEGREES(ATAN(-(COS(RADIANS($S$6))/SIN(RADIANS($S$6)))*COS(RADIANS(J55-$S$7)))) -> -46.857342 | U55: 15 | V55: 18ᶜ 18ᵐ (274.5°) | W55: −15.9°
F56: 9 | G56: 8 | H56: 0 | I56: =(((H56/60)+G56)/60)+F56 -> 9.1333333 | J56: =((((H56/60)+G56)/60)+F56)*15 -> 137 | N56: =DEGREES(ATAN(-(COS(RADIANS($S$6))/SIN(RADIANS($S$6)))*COS(RADIANS(J56-$S$7)))) -> -47.606513 | U56: 30 | V56: 18ᶜ 40ᵐ (279.9°) | W56: −2.6°
F57: 9 | G57: 12 | H57: 0 | I57: =(((H57/60)+G57)/60)+F57 -> 9.2 | J57: =((((H57/60)+G57)/60)+F57)*15 -> 138 | N57: =DEGREES(ATAN(-(COS(RADIANS($S$6))/SIN(RADIANS($S$6)))*COS(RADIANS(J57-$S$7)))) -> -48.326373 | U57: 45 | V57: 19ᶜ 14ᵐ (288.5°) | W57: +10.7°
F58: 9 | G58: 16 | H58: 0 | I58: =(((H58/60)+G58)/60)+F58 -> 9.2666667 | J58: =((((H58/60)+G58)/60)+F58)*15 -> 139 | N58: =DEGREES(ATAN(-(COS(RADIANS($S$6))/SIN(RADIANS($S$6)))*COS(RADIANS(J58-$S$7)))) -> -49.018038 | U58: 60 | V58: 19ᶜ 44ᵐ (296.0°) | W58: +23.9°
F59: 9 | G59: 20 | H59: 0 | I59: =(((H59/60)+G59)/60)+F59 -> 9.3333333 | J59: =((((H59/60)+G59)/60)+F59)*15 -> 140 | N59: =DEGREES(ATAN(-(COS(RADIANS($S$6))/SIN(RADIANS($S$6)))*COS(RADIANS(J59-$S$7)))) -> -49.682593 | U59: 75 | V59: 20ᶜ 21ᵐ (305.3°) | W59: +36.4°
F60: 9 | G60: 24 | H60: 0 | I60: =(((H60/60)+G60)/60)+F60 -> 9.4 | J60: =((((H60/60)+G60)/60)+F60)*15 -> 141 | N60: =DEGREES(ATAN(-(COS(RADIANS($S$6))/SIN(RADIANS($S$6)))*COS(RADIANS(J60-$S$7)))) -> -50.321083 | U60: 90 | V60: 21ᶜ 07ᵐ (316.9°) | W60: +48.2°
F61: 9 | G61: 28 | H61: 0 | I61: =(((H61/60)+G61)/60)+F61 -> 9.4666667 | J61: =((((H61/60)+G61)/60)+F61)*15 -> 142 | N61: =DEGREES(ATAN(-(COS(RADIANS($S$6))/SIN(RADIANS($S$6)))*COS(RADIANS(J61-$S$7)))) -> -50.934514 | U61: 105 | V61: 22ᶜ 31ᵐ (337.9°) | W61: +58.1°
F62: 9 | G62: 32 | H62: 0 | I62: =(((H62/60)+G62)/60)+F62 -> 9.5333333 | J62: =((((H62/60)+G62)/60)+F62)*15 -> 143 | N62: =DEGREES(ATAN(-(COS(RADIANS($S$6))/SIN(RADIANS($S$6)))*COS(RADIANS(J62-$S$7)))) -> -51.523857 | U62: 120 | V62: 01ᶜ 13ᵐ (18.4°) | W62: +62.8°
F63: 9 | G63: 36 | H63: 0 | I63: =(((H63/60)+G63)/60)+F63 -> 9.6 | J63: =((((H63/60)+G63)/60)+F63)*15 -> 144 | N63: =DEGREES(ATAN(-(COS(RADIANS($S$6))/SIN(RADIANS($S$6)))*COS(RADIANS(J63-$S$7)))) -> -52.090042 | U63: 135 | V63: 02ᶜ 31ᵐ (37.9°) | W63: +60.5°
...
